Workbook
Name NativeTimeline_Dashboard_Order_Date: #N/A
Name Slicer_Category: #REF!
Name Slicer_Category1: #N/A
Name Slicer_MentorName: #REF!
Name Slicer_Platform: #REF!
Name Slicer_Region: #N/A

Sheet Sales_data
A1: Order_ID | B1: Customer_ID | C1: Product_ID | D1: Order_Date | E1: Delivery_Date | F1: Customer_Name | G1: Gender | H1: DOB | I1: City | J1: Region | K1: Category | L1: Product_Name | M1: Quantity | N1: Unit_Price | O1: Discount_% | P1: Sales | Q1: Rating | R1: Payment_Mode | S1: Salesperson | T1: Email | U1: Phone | V1: Order_Status
A2: ORD10001 | B2: C008 | C2: P202 | D2: 18/09/2025 | E2: 22/09/2025 | F2: Kavya Nair | G2: Female | H2: 01/08/1976 | I2: Hyderabad | J2: South | K2: Home Appliances | L2: Iron | M2: 4 | N2: 2200 | O2: 10 | P2: 7920 | Q2: 4 | R2: Cash | S2: Ritika | T2: KAvya.nair@company.com | U2: 9431429797 | V2: Completed
A3: ORD10002 | B3: C008 | C3: P104 | D3: 27/04/2025 | E3: 04/05/2025 | F3: Kavya Nair | G3: Female | H3: 16/10/2000 | I3: Delhi | J3: North | K3: Electronics | L3: Monitor | M3: 17 | N3: 12000 | O3: 10 | P3: 183600 | Q3: 1 | R3: NetBanking | S3: Rahul | T3: kavya.nair@company.com | U3: 9129865339 | V3: Completed
A4: ORD10003 | B4: C010 | C4: P101 | D4: 03/09/2025 | E4: 14/09/2025 | F4: pooja shah | G4: Female | H4: 16/09/1994 | I4: Bengaluru | J4: South | K4: Electronics | L4: Laptop | M4: 5 | N4: 55000 | O4: 5 | P4: 261250 | Q4: 3 | R4: NetBanking | S4: Aisha | T4: pooja.shah@company.com | U4: 9380975626 | V4: Pending
A5: ORD10002 | B5: C008 | C5: P202 | D5: 21/03/2026 | E5: 02/04/2026 | F5: Kavya Nair | G5: Female | H5: 07/03/2004 | I5: Bengaluru | J5: South | K5: Home Appliances | L5: Iron | M5: 5 | N5: 2200 | O5: 5 | P5: 10450 | Q5: 5 | R5: NetBanking | S5: Aisha | T5: kavya.nair@company.com | U5: 9600261125 | V5: Cancelled
A6: ORD10005 | B6: C009 | C6: P103 | D6: 27/09/2025 | E6: 07/10/2025 | F6: Mohit Verma | G6: Male | H6: 13/04/1976 | I6: Delhi | J6: North | K6: Electronics | L6: Keyboard | M6: 8 | N6: 1200 | O6: 5 | P6: 9120 | Q6: 2 | R6: Card | S6: Aisha | T6: mohit.verma@company.com | U6: 9724635978 | V6: Pending
A7: ORD10006 | B7: C007 | C7: P202 | D7: 04/01/2026 | E7: 12/01/2026 | F7: arjun Rao | G7: Male | H7: 07/02/1988 | I7: Hyderabad | J7: South | K7: Home Appliances | L7: Iron | M7: 4 | N7: 2200 | O7: 0 | P7: 8800 | Q7: 1 | R7: UPI | S7: Ritika | T7: arjun.rao@company.com | U7: 9780584905 | V7: Completed
A8: ORD10007 | B8: C008 | C8: P201 | D8: 31/02/2025 | E8: 25/02/2026 | F8: Kavya Nair | G8: Female | H8: 20/03/2003 | I8: Hyderabad | J8: South | K8: Home Appliances | L8: Mixer | M8: 2 | N8: 3500 | O8: 5 | P8: 6650 | Q8: 1 | R8: UPI | S8: Ritika | T8: kavya.nair@company.com | U8: 9958252176 | V8: Completed
A9: ORD10008 | B9: C002 | C9: P104 | D9: 13/04/2025 | E9: 19/04/2025 | F9: Priya Patel | G9: Female | H9: 07/03/1995 | I9: Mumbai | J9: West | K9: Electronics | L9: Monitor | M9: 14 | N9: 12000 | O9: 15 | P9: 142800 | Q9: 4 | R9: NetBanking | S9: Ritika | T9: priYa.patel@company.com | U9: 9705521654 | V9: Completed
A10: ORD10009 | B10: C008 | C10: P104 | D10: 31/01/2026 | E10: 02/02/2026 | F10: kavya Nair | G10: Female | H10: 06/04/1997 | I10: Pune | J10: West | K10: Electronics | L10: Monitor | M10: 4 | N10: 12000 | O10: 15 | P10: 40800 | Q10: 4 | R10: UPI | S10: Neha | T10: kavya.nair@company.com | U10: 9588041011 | V10: Completed
A11: ORD10010 | B11: C002 | C11: P301 | D11: 25/03/2025 | E11: 27/03/2025 | F11: Priya Patel | G11: Female | H11: 07/01/1990 | I11: Mumbai | J11: West | K11: Stationery | L11: Notebook | M11: 6 | N11: 60 | O11: 0 | P11: 360 | Q11: 4 | R11: Card | S11: Neha | T11: PRiya.patel@company.com | U11: 9340540608 | V11: Completed
A12: ORD10011 | B12: C003 | C12: P202 | D12: 19/09/2025 | E12: 23/09/2025 | F12: Rohit Singh | G12: Male | H12: 10/05/1982 | I12: Delhi | J12: North | K12: Home Appliances | L12: Iron | M12: -3 | N12: 2200 | O12: 0 | P12: 35200 | Q12: 2 | R12: Card | S12: Rahul | T12: rohit.singh@company.com | U12: 9521710321 | V12: Pending
A13: ORD10012 | B13: C008 | C13: P201 | D13: 08/03/2025 | E13: 15/03/2025 | F13: Kavya Nair | G13: Female | H13: 23/01/1982 | I13: Ahmedabad | J13: West | K13: Home Appliances | L13: Mixer | M13: 10 | N13: 3500 | O13: 5 | P13: 33250 | Q13: 5 | R13: Card | S13: Aisha | T13: kavya.nair@company.com | U13: 9123535241 | V13: Cancelled
... A39: ORD10038 | B39: C006 | C39: P201 | D39: 08/03/2026 | E39: 20/03/2026 | F39: Sneha Joshi | G39: Female | H39: 21/06/1980 | I39: Delhi | J39: North | K39: Home Appliances | L39: Mixer | M39: 20 | N39: 3500 | O39: 10 | P39: 63000 | Q39: 3 | R39: Card | S39: Rahul | T39: sneha.joshi@company.com | U39: 9283578533 | V39: Cancelled
A40: ORD10039 | B40: C008 | C40: P302 | D40: 13/02/2025 | E40: 19/02/2025 | F40: Kavya Nair | G40: Female | H40: 17/06/1979 | I40: Pune | J40: West | K40: Stationery | L40: Pen | M40: 5 | N40: 1200 | O40: 0 | P40: 100 | Q40: 1 | R40: Cash | S40: Rahul | T40: kavya.nair@company.com | U40: 9963005771 | V40: Cancelled
A41: ORD10040 | B41: C010 | C41: P203 | D41: 05/10/2025 | E41: 15/10/2025 | F41: Pooja Shah | G41: Female | H41: 18/06/1992 | I41: Mumbai | J41: West | K41: Home Appliances | L41: Microwave | M41: 20 | N41: 8500 | O41: 0 | P41: 170000 | Q41: 1 | R41: UPI | S41: Neha | T41: pooja.shah@company.com | U41: 9484632635 | V41: Cancelled
A42: ORD10041 | B42: C007 | C42: P301 | D42: 10/02/2026 | E42: 12/02/2026 | F42: Arjun Rao | G42: Male | H42: 06/06/1994 | I42: Bengaluru | J42: South | K42: Stationery | L42: Notebook | M42: 8 | N42: 60 | O42: 15 | P42: 408 | Q42: 5 | R42: UPI | S42: Rahul | T42: arjun.rao@company.com | U42: 9276319484 | V42: Pending
A43: ORD10042 | B43: C010 | C43: P201 | D43: 04/06/2025 | E43: 16/06/2025 | F43: Pooja Shah | G43: Female | H43: 22/09/1988 | I43: Pune | J43: West | K43: Home Appliances | L43: Mixer | M43: 8 | N43: 3500 | O43: 5 | P43: 26600 | Q43: 1 | R43: Card | S43: Neha | T43: pooja.shah@company.com | U43: 9619034852 | V43: Pending
A44: ORD10043 | B44: C009 | C44: P203 | D44: 08/02/2026 | E44: 14/02/2026 | F44: Mohit Verma | G44: Male | H44: 14/07/2001 | I44: Jaipur | J44: North | K44: Home Appliances | L44: Microwave | M44: 1 | N44: 8500 | O44: 0 | P44: 8500 | Q44: 2 | R44: Card | S44: Neha | T44: mohit.verma@company.com | U44: 9636416962 | V44: Pending
A45: ORD10044 | B45: C001 | C45: P303 | D45: 30/03/2025 | E45: 31/03/2025 | F45: amit Sharma | G45: Male | H45: 09/08/1991 | I45: Pune | J45: West | K45: Stationery | L45: Marker | M45: 8 | N45: 45 | O45: 15 | P45: 306 | Q45: 2 | R45: Card | S45: Aisha | T45: amit.sharma@company.com | U45: 9357133880 | V45: Completed
A46: ORD10045 | B46: C006 | C46: P202 | D46: 25/04/2025 | E46: 28/04/2025 | F46: Sneha Joshi | G46: Female | H46: 21/10/1988 | I46: Pune | J46: West | K46: Home Appliances | L46: Iron | M46: 16 | N46: 2200 | O46: 5 | P46: 33440 | Q46: 5 | R46: Card | S46: Aisha | T46: sneha.joshi@company.com | U46: 9575210324 | V46: Cancelled
A47: ORD10046 | B47: C009 | C47: P201 | D47: 13/10/2025 | E47: 23/10/2025 | F47: Mohit Verma | G47: Male | H47: 19/11/2002 | I47: Bengaluru | J47: South | K47: Home Appliances | L47: Mixer | M47: 19 | N47: 3500 | O47: 20 | P47: 53200 | Q47: 3 | R47: Cash | S47: Karan | T47: mohit.verma@company.com | U47: 9276080204 | V47: Cancelled
A48: ORD10047 | B48: C006 | C48: P102 | D48: 11/10/2025 | E48: 14/10/2025 | F48: Sneha Joshi | G48: Female | H48: 06/07/2000 | I48: Pune | J48: West | K48: Electronics | L48: Mouse | M48: 15 | N48: 700 | O48: 15 | P48: 8925 | Q48: 4 | R48: UPI | S48: Neha | T48: sneha.joshicompany.com | U48: 9856624471 | V48: Completed
A49: ORD10048 | B49: C006 | C49: P102 | D49: 27/11/2025 | E49: 03/12/2025 | F49: Sneha Joshi | G49: Female | H49: 26/11/1998 | I49: Jaipur | J49: North | K49: Electronics | L49: Mouse | M49: 19 | N49: 700 | O49: 20 | P49: 10640 | Q49: 1 | R49: Cash | S49: Neha | T49: sneha.joshi@company.com | U49: 9238141322 | V49: Completed
A50: ORD10049 | B50: C009 | C50: P104 | D50: 19/04/2026 | F50: Mohit Verma | G50: Male | H50: 03/06/1996 | I50: Delhi | J50: North | K50: Electronics | L50: Monitor | M50: 19 | N50: 12000 | O50: 0 | P50: 228000 | Q50: 1 | R50: NetBanking | S50: Aisha | T50: mohit.verma@company.com | U50: 9890380030 | V50: Completed
A51: ORD10050 | B51: C004 | C51: P103 | D51: 19/04/2026 | E51: 21/04/2026 | F51: Anita Gupta | G51: Female | H51: 15/03/1987 | I51: Pune | J51: West | K51: Electronics | L51: Keyboard | M51: 6 | N51: 1200 | O51: 5 | P51: 6840 | Q51: 2 | R51: Cash | S51: Ritika | T51: anita.gupta@company.com | U51: 9495893170 | V51: Pending
A52: ORD10051 | B52: C010 | C52: P202 | D52: 28/03/2025 | E52: 07/04/2025 | F52: POoja Shah | G52: Female | H52: 20/02/1979 | I52: Bengaluru | J52: South | K52: Home Appliances | L52: Iron | M52: 7 | N52: 2200 | O52: 15 | P52: 13090 | Q52: 1 | R52: UPI | S52: Aisha | T52: pooja.shah@company.com | U52: 9485166307 | V52: Completed
A53: ORD10052 | B53: C002 | C53: P301 | D53: 25/08/2025 | E53: 28/08/2025 | F53: Priya Patel | G53: Female | H53: 09/08/2000 | I53: Jaipur | J53: North | K53: Stationery | L53: Notebook | M53: 8 | N53: 60 | O53: 10 | P53: 432 | Q53: 5 | R53: Card | S53: Aisha | T53: priya.patel@company.com | U53: 9924709648 | V53: Cancelled
A54: ORD10053 | B54: C005 | C54: P101 | D54: 19/08/2025 | E54: 23/08/2025 | F54: Vikas Mehta | G54: Male | H54: 17/01/1976 | I54: Kolkata | J54: East | K54: Electronics | L54: Laptop | M54: 12 | N54: 55000 | O54: 5 | P54: 627000 | Q54: 2 | R54: UPI | S54: Rahul | T54: vikas.mehta@company.com | U54: 9350554626 | V54: Pending
A55: ORD10054 | B55: C008 | C55: P102 | D55: 27/07/2025 | E55: 05/08/2025 | F55: Kavya Nair | G55: Female | H55: 04/04/1975 | I55: Jaipur | J55: North | K55: Electronics | L55: Mouse | M55: 3 | N55: 700 | O55: 0 | P55: 2100 | Q55: 3 | R55: Card | S55: Karan | T55: kavya.nair@company.com | U55: 9743295580 | V55: Cancelled
A56: ORD10055 | B56: C003 | C56: P301 | D56: 21/02/2025 | E56: 26/02/2025 | F56: RoHit Singh | G56: Male | H56: 11/12/1976 | I56: Ahmedabad | J56: West | K56: Stationery | L56: Notebook | M56: 19 | N56: 60 | O56: 15 | P56: 969 | Q56: 4 | R56: Card | S56: Rahul | T56: rohit.singh@company.com | U56: 9822926495 | V56: Cancelled
A57: ORD10056 | B57: C001 | C57: P301 | D57: 10/08/2025 | E57: 11/08/2025 | F57: Amit Sharma | G57: Male | H57: 03/12/1979 | I57: Jaipur | J57: North | K57: Stationery | L57: Notebook | M57: 9 | N57: 60 | O57: 20 | P57: 432 | Q57: 1 | R57: NetBanking | S57: Neha | T57: amit.sharma@company.com | U57: 9518298190 | V57: Pending
A58: ORD10057 | B58: C001 | C58: P102 | D58: 24/03/2026 | E58: 30/03/2026 | F58: Amit Sharma | G58: Male | H58: 27/12/1978 | I58: Bengaluru | J58: South | K58: Electronics | L58: Mouse | M58: 6 | N58: 700 | O58: 0 | P58: 4200 | Q58: 4 | R58: UPI | S58: Rahul | T58: amit.sharmcompany.com | U58: 9366223547 | V58: Cancelled
A59: ORD10058 | B59: C003 | C59: P303 | D59: 13/03/2026 | E59: 19/03/2026 | F59: Rohit Singh | G59: Male | H59: 15/04/1975 | I59: Delhi | J59: North | K59: Stationery | L59: Marker | M59: 18 | N59: 45 | O59: 5 | P59: 769.5 | Q59: 1 | R59: Card | S59: Aisha | T59: rohit.singh@company.com | U59: 9701988524 | V59: Pending
A60: ORD10059 | B60: C007 | C60: P302 | D60: 15/06/2025 | E60: 26/06/2025 | F60: Arjun Rao | G60: Male | H60: 19/12/1988 | I60: Jaipur | J60: North | K60: Stationery | L60: Pen | M60: 8 | N60: 20 | O60: 5 | P60: 152 | Q60: 1 | R60: Card | S60: Ritika | T60: arjun.rao@company.com | U60: 9836327649 | V60: completed
A61: ORD10060 | B61: C005 | C61: P102 | D61: 05/03/2025 | E61: 06/03/2025 | F61: Vikas Mehta | G61: Male | H61: 07/03/1979 | I61: Jaipur | J61: North | K61: Electronics | L61: Mouse | M61: 8 | N61: 700 | O61: 10 | P61: 5040 | Q61: 1 | R61: NetBanking | S61: Aisha | T61: Vikas.mehta@company.com | U61: 9261800516 | V61: Cancelled
A62: ORD10061 | B62: C008 | C62: P302 | D62: 09/04/2026 | E62: 19/04/2026 | F62: Kavya Nair | G62: Female | H62: 17/12/2003 | I62: Delhi | J62: North | K62: Stationery | L62: Pen | M62: 7 | N62: 20 | O62: 15 | P62: 119 | Q62: 5 | R62: Card | S62: Rahul | T62: kavya.nair@company.com | U62: 9950802015 | V62: Completed
... A74: ORD10073 | B74: C008 | C74: P103 | D74: 13/12/2025 | E74: 23/12/2025 | F74: Kavya Nair | G74: Female | H74: 22/09/1981 | I74: Jaipur | J74: North | K74: Electronics | L74: Keyboard | M74: 1 | N74: 1200 | O74: 5 | P74: 1140 | Q74: 3 | R74: UPI | S74: Aisha | T74: kavya.nair@company.com | U74: 9808988530 | V74: Cancelled
A75: ORD10074 | B75: C010 | C75: P202 | D75: 04/02/2026 | E75: 16/02/2026 | F75: Pooja Shah | G75: Female | H75: 20/06/1980 | J75: South | K75: Home Appliances | L75: Iron | M75: 1 | N75: 2200 | O75: 15 | P75: 1870 | Q75: 4 | R75: Card | S75: Aisha | T75: pooja.shah@company.com | U75: 9286410494 | V75: Completed
A76: ORD10075 | B76: C003 | C76: P103 | D76: 26/01/2026 | E76: 28/01/2026 | F76: Rohit Singh | G76: Male | H76: 02/11/1982 | I76: Pune | J76: West | K76: Electronics | L76: Keyboard | M76: 3 | N76: 1200 | O76: 10 | P76: 3240 | Q76: 5 | R76: Cash | S76: Rahul | T76: rohit.singh@company.com | U76: 9311555196 | V76: Completed
...

Sheet Product_master
A1: Product_ID | B1: Product_Name | C1: Category | D1: Supplier | E1: Cost_Price | F1: Warranty_Months
A2: P101 | B2: Laptop | C2: Electronics | D2: TechHub | E2: 41250 | F2: 12
A3: P102 | B3: Mouse | C3: Electronics | D3: TechHub | E3: 525 | F3: 24
A4: P103 | B4: Keyboard | C4: Electronics | D4: TechHub | E4: 900 | F4: 6
A5: P104 | B5: Monitor | C5: Electronics | D5: Global Trade | E5: 9000 | F5: 24
A6: P201 | B6: Mixer | C6: Home Appliances | D6: Global Trade | E6: 2625 | F6: 6
A7: P202 | B7: Iron | C7: Home Appliances | D7: Global Trade | E7: 1650 | F7: 24
A8: P203 | B8: Microwave | C8: Home Appliances | D8: TechHub | E8: 6375 | F8: 24
A9: P301 | B9: Notebook | C9: Stationery | D9: ABC Corp | E9: 45 | F9: 12
A10: P302 | B10: Pen | C10: Stationery | D10: Prime Supplies | E10: 15 | F10: 12
A11: P303 | B11: Marker | C11: Stationery | D11: TechHub | E11: 33.75 | F11: 12

Sheet Customer_master
A1: Customer_ID | B1: Customer_Name | C1: Membership | D1: State
A2: C001 | B2: Amit Sharma | C2: Silver | D2: RJ
A3: C002 | B3: Priya Patel | C3: Platinum | D3: WB
A4: C003 | B4: Rohit Singh | C4: Gold | D4: DL
A5: C004 | B5: Anita Gupta | C5: Gold | D5: WB
A6: C005 | B6: Vikas Mehta | C6: Gold | D6: DL
A7: C006 | B7: Sneha Joshi | C7: Gold | D7: WB
A8: C007 | B8: Arjun Rao | C8: Silver | D8: RJ
A9: C008 | B9: Kavya Nair | C9: Silver | D9: WB
A10: C009 | B10: Mohit Verma | C10: Platinum | D10: KA
A11: C010 | B11: Pooja Shah | C11: Silver | D11: WB

Sheet Q1
A1: Order_ID | B1: Customer_ID | C1: Product_ID | D1: Order_Date | E1: Delivery_Date | F1: Customer_Name | G1: Gender | H1: DOB | I1: City | J1: Region | K1: Category | L1: Product_Name | M1: Quantity | N1: Unit_Price | O1: Discount_% | P1: Sales | Q1: Rating | R1: Payment_Mode | S1: Salesperson | T1: Email | U1: Phone | V1: Order_Status | W1: Customer Classification
A2: ORD10001 | B2: C008 | C2: P202 | D2: 18/09/2025 | E2: 22/09/2025 | F2: Kavya Nair | G2: Female | H2: 01/08/1976 | I2: Hyderabad | J2: South | K2: Home Appliances | L2: Iron | M2: 4 | N2: 2200 | O2: 10 | P2: 7920 | Q2: 4 | R2: Cash | S2: Ritika | T2: KAvya.nair@company.com | U2: 9431429797 | V2: Completed | W2: {=_xlfn.IFS(OR(V2="Cancelled", Q2<=2), "Blacklisted", AND(P2>=100000, Q2>=4, O2<=0.1, V2="Completed"), "Platinum", AND(P2>=50000, P2<=99999, Q2>=3, V2="Completed"), "Gold", AND(Q2<50000, V2="Completed"), "Silver")} -> Silver
A3: ORD10002 | B3: C008 | C3: P104 | D3: 27/04/2025 | E3: 04/05/2025 | F3: Kavya Nair | G3: Female | H3: 16/10/2000 | I3: Delhi | J3: North | K3: Electronics | L3: Monitor | M3: 17 | N3: 12000 | O3: 10 | P3: 183600 | Q3: 1 | R3: NetBanking | S3: Rahul | T3: kavya.nair@company.com | U3: 9129865339 | V3: Completed | W3: {=_xlfn.IFS(OR(V3="Cancelled", Q3<=2), "Blacklisted", AND(P3>=100000, Q3>=4, O3<=0.1, V3="Completed"), "Platinum", AND(P3>=50000, P3<=99999, Q3>=3, V3="Completed"), "Gold", AND(Q3<50000, V3="Completed"), "Silver")} -> Blacklisted
A4: ORD10003 | B4: C010 | C4: P101 | D4: 03/09/2025 | E4: 14/09/2025 | F4: Pooja Shah | G4: Female | H4: 16/09/1994 | I4: Bengaluru | J4: South | K4: Electronics | L4: Laptop | M4: 5 | N4: 55000 | O4: 5 | P4: 261250 | Q4: 3 | R4: NetBanking | S4: Aisha | T4: pooja.shah@company.com | U4: 9380975626 | V4: Pending | W4: {=_xlfn.IFS(OR(V4="Cancelled", Q4<=2), "Blacklisted", AND(P4>=100000, Q4>=4, O4<=0.1, V4="Completed"), "Platinum", AND(P4>=50000, P4<=99999, Q4>=3, V4="Completed"), "Gold", AND(Q4<50000, V4="Completed"), "Silver", V4="Pending", "Pending")} -> Pending
A5: ORD10002 | B5: C008 | C5: P202 | D5: 21/03/2026 | E5: 02/04/2026 | F5: Kavya Nair | G5: Female | H5: 07/03/2004 | I5: Bengaluru | J5: South | K5: Home Appliances | L5: Iron | M5: 5 | N5: 2200 | O5: 5 | P5: 10450 | Q5: 5 | R5: NetBanking | S5: Aisha | T5: kavya.nair@company.com | U5: 9600261125 | V5: Cancelled | W5: {=_xlfn.IFS(OR(V5="Cancelled", Q5<=2), "Blacklisted", AND(P5>=100000, Q5>=4, O5<=0.1, V5="Completed"), "Platinum", AND(P5>=50000, P5<=99999, Q5>=3, V5="Completed"), "Gold", AND(Q5<50000, V5="Completed"), "Silver", V5="Pending", "Pending")} -> Blacklisted
A6: ORD10005 | B6: C009 | C6: P103 | D6: 27/09/2025 | E6: 07/10/2025 | F6: Mohit Verma | G6: Male | H6: 13/04/1976 | I6: Delhi | J6: North | K6: Electronics | L6: Keyboard | M6: 8 | N6: 1200 | O6: 5 | P6: 9120 | Q6: 2 | R6: Card | S6: Aisha | T6: mohit.verma@company.com | U6: 9724635978 | V6: Pending | W6: {=_xlfn.IFS(OR(V6="Cancelled", Q6<=2), "Blacklisted", AND(P6>=100000, Q6>=4, O6<=0.1, V6="Completed"), "Platinum", AND(P6>=50000, P6<=99999, Q6>=3, V6="Completed"), "Gold", AND(Q6<50000, V6="Completed"), "Silver", V6="Pending", "Pending")} -> Blacklisted
A7: ORD10006 | B7: C007 | C7: P202 | D7: 04/01/2026 | E7: 12/01/2026 | F7: Arjun Rao | G7: Male | H7: 07/02/1988 | I7: Hyderabad | J7: South | K7: Home Appliances | L7: Iron | M7: 4 | N7: 2200 | O7: 0 | P7: 8800 | Q7: 1 | R7: UPI | S7: Ritika | T7: arjun.rao@company.com | U7: 9780584905 | V7: Completed | W7: {=_xlfn.IFS(OR(V7="Cancelled", Q7<=2), "Blacklisted", AND(P7>=100000, Q7>=4, O7<=0.1, V7="Completed"), "Platinum", AND(P7>=50000, P7<=99999, Q7>=3, V7="Completed"), "Gold", AND(Q7<50000, V7="Completed"), "Silver", V7="Pending", "Pending")} -> Blacklisted
A8: ORD10007 | B8: C008 | C8: P201 | D8: 31/02/2025 | E8: 25/02/2026 | F8: Kavya Nair | G8: Female | H8: 20/03/2003 | I8: Hyderabad | J8: South | K8: Home Appliances | L8: Mixer | M8: 2 | N8: 3500 | O8: 5 | P8: 6650 | Q8: 1 | R8: UPI | S8: Ritika | T8: kavya.nair@company.com | U8: 9958252176 | V8: Completed | W8: {=_xlfn.IFS(OR(V8="Cancelled", Q8<=2), "Blacklisted", AND(P8>=100000, Q8>=4, O8<=0.1, V8="Completed"), "Platinum", AND(P8>=50000, P8<=99999, Q8>=3, V8="Completed"), "Gold", AND(Q8<50000, V8="Completed"), "Silver", V8="Pending", "Pending")} -> Blacklisted
A9: ORD10008 | B9: C002 | C9: P104 | D9: 13/04/2025 | E9: 19/04/2025 | F9: Priya Patel | G9: Female | H9: 07/03/1995 | I9: Mumbai | J9: West | K9: Electronics | L9: Monitor | M9: 14 | N9: 12000 | O9: 15 | P9: 142800 | Q9: 4 | R9: NetBanking | S9: Ritika | T9: priYa.patel@company.com | U9: 9705521654 | V9: Completed | W9: {=_xlfn.IFS(OR(V9="Cancelled", Q9<=2), "Blacklisted", AND(P9>=100000, Q9>=4, O9<=0.1, V9="Completed"), "Platinum", AND(P9>=50000, P9<=99999, Q9>=3, V9="Completed"), "Gold", AND(Q9<50000, V9="Completed"), "Silver", V9="Pending", "Pending")} -> Silver
A10: ORD10009 | B10: C008 | C10: P104 | D10: 31/01/2026 | E10: 02/02/2026 | F10: Kavya Nair | G10: Female | H10: 06/04/1997 | I10: Pune | J10: West | K10: Electronics | L10: Monitor | M10: 4 | N10: 12000 | O10: 15 | P10: 40800 | Q10: 4 | R10: UPI | S10: Neha | T10: kavya.nair@company.com | U10: 9588041011 | V10: Completed | W10: {=_xlfn.IFS(OR(V10="Cancelled", Q10<=2), "Blacklisted", AND(P10>=100000, Q10>=4, O10<=0.1, V10="Completed"), "Platinum", AND(P10>=50000, P10<=99999, Q10>=3, V10="Completed"), "Gold", AND(Q10<50000, V10="Completed"), "Silver", V10="Pending", "Pending")} -> Silver
A11: ORD10010 | B11: C002 | C11: P301 | D11: 25/03/2025 | E11: 27/03/2025 | F11: Priya Patel | G11: Female | H11: 07/01/1990 | I11: Mumbai | J11: West | K11: Stationery | L11: Notebook | M11: 6 | N11: 60 | O11: 0 | P11: 360 | Q11: 4 | R11: Card | S11: Neha | T11: PRiya.patel@company.com | U11: 9340540608 | V11: Completed | W11: {=_xlfn.IFS(OR(V11="Cancelled", Q11<=2), "Blacklisted", AND(P11>=100000, Q11>=4, O11<=0.1, V11="Completed"), "Platinum", AND(P11>=50000, P11<=99999, Q11>=3, V11="Completed"), "Gold", AND(Q11<50000, V11="Completed"), "Silver", V11="Pending", "Pending")} -> Silver
A12: ORD10011 | B12: C003 | C12: P202 | D12: 19/09/2025 | E12: 23/09/2025 | F12: Rohit Singh | G12: Male | H12: 10/05/1982 | I12: Delhi | J12: North | K12: Home Appliances | L12: Iron | M12: -3 | N12: 2200 | O12: 0 | P12: 35200 | Q12: 2 | R12: Card | S12: Rahul | T12: rohit.singh@company.com | U12: 9521710321 | V12: Pending | W12: {=_xlfn.IFS(OR(V12="Cancelled", Q12<=2), "Blacklisted", AND(P12>=100000, Q12>=4, O12<=0.1, V12="Completed"), "Platinum", AND(P12>=50000, P12<=99999, Q12>=3, V12="Completed"), "Gold", AND(Q12<50000, V12="Completed"), "Silver", V12="Pending", "Pending")} -> Blacklisted
A13: ORD10012 | B13: C008 | C13: P201 | D13: 08/03/2025 | E13: 15/03/2025 | F13: Kavya Nair | G13: Female | H13: 23/01/1982 | I13: Ahmedabad | J13: West | K13: Home Appliances | L13: Mixer | M13: 10 | N13: 3500 | O13: 5 | P13: 33250 | Q13: 5 | R13: Card | S13: Aisha | T13: kavya.nair@company.com | U13: 9123535241 | V13: Cancelled | W13: {=_xlfn.IFS(OR(V13="Cancelled", Q13<=2), "Blacklisted", AND(P13>=100000, Q13>=4, O13<=0.1, V13="Completed"), "Platinum", AND(P13>=50000, P13<=99999, Q13>=3, V13="Completed"), "Gold", AND(Q13<50000, V13="Completed"), "Silver", V13="Pending", "Pending")} -> Blacklisted
A14: ORD10013 | B14: C002 | C14: P202 | D14: 10/01/2025 | E14: 15/01/2025 | F14: Priya Patel | G14: Female | H14: 06/07/1992 | I14: Pune | J14: West | K14: Home Appliances | L14: Iron | M14: 15 | N14: 2200 | O14: 10 | P14: 29700 | Q14: 1 | R14: UPI | S14: Neha | T14: priya.patel@company.com | U14: 9367316892 | V14: Pending | W14: {=_xlfn.IFS(OR(V14="Cancelled", Q14<=2), "Blacklisted", AND(P14>=100000, Q14>=4, O14<=0.1, V14="Completed"), "Platinum", AND(P14>=50000, P14<=99999, Q14>=3, V14="Completed"), "Gold", AND(Q14<50000, V14="Completed"), "Silver", V14="Pending", "Pending")} -> Blacklisted
A15: ORD10014 | B15: C003 | C15: P202 | D15: 09/03/2025 | E15: 13/03/2025 | F15: Rohit Singh | G15: Male | H15: 19/03/2002 | I15: Mumbai | J15: West | K15: Home Appliances | L15: Iron | M15: 17 | N15: 2200 | O15: 5 | P15: 35530 | Q15: 1 | R15: Cash | S15: Karan | T15: rOhit.singh@company.com | U15: 9778489803 | V15: Completed | W15: {=_xlfn.IFS(OR(V15="Cancelled", Q15<=2), "Blacklisted", AND(P15>=100000, Q15>=4, O15<=0.1, V15="Completed"), "Platinum", AND(P15>=50000, P15<=99999, Q15>=3, V15="Completed"), "Gold", AND(Q15<50000, V15="Completed"), "Silver", V15="Pending", "Pending")} -> Blacklisted
... A39: ORD10038 | B39: C006 | C39: P201 | D39: 08/03/2026 | E39: 20/03/2026 | F39: Sneha Joshi | G39: Female | H39: 21/06/1980 | I39: Delhi | J39: North | K39: Home Appliances | L39: Mixer | M39: 20 | N39: 3500 | O39: 10 | P39: 63000 | Q39: 3 | R39: Card | S39: Rahul | T39: sneha.joshi@company.com | U39: 9283578533 | V39: Cancelled | W39: {=_xlfn.IFS(OR(V39="Cancelled", Q39<=2), "Blacklisted", AND(P39>=100000, Q39>=4, O39<=0.1, V39="Completed"), "Platinum", AND(P39>=50000, P39<=99999, Q39>=3, V39="Completed"), "Gold", AND(Q39<50000, V39="Completed"), "Silver", V39="Pending", "Pending")} -> Blacklisted
A40: ORD10039 | B40: C008 | C40: P302 | D40: 13/02/2025 | E40: 19/02/2025 | F40: Kavya Nair | G40: Female | H40: 17/06/1979 | I40: Pune | J40: West | K40: Stationery | L40: Pen | M40: 5 | N40: 1200 | O40: 0 | P40: 100 | Q40: 1 | R40: Cash | S40: Rahul | T40: kavya.nair@company.com | U40: 9963005771 | V40: Cancelled | W40: {=_xlfn.IFS(OR(V40="Cancelled", Q40<=2), "Blacklisted", AND(P40>=100000, Q40>=4, O40<=0.1, V40="Completed"), "Platinum", AND(P40>=50000, P40<=99999, Q40>=3, V40="Completed"), "Gold", AND(Q40<50000, V40="Completed"), "Silver", V40="Pending", "Pending")} -> Blacklisted
A41: ORD10040 | B41: C010 | C41: P203 | D41: 05/10/2025 | E41: 15/10/2025 | F41: Pooja Shah | G41: Female | H41: 18/06/1992 | I41: Mumbai | J41: West | K41: Home Appliances | L41: Microwave | M41: 20 | N41: 8500 | O41: 0 | P41: 170000 | Q41: 1 | R41: UPI | S41: Neha | T41: pooja.shah@company.com | U41: 9484632635 | V41: Cancelled | W41: {=_xlfn.IFS(OR(V41="Cancelled", Q41<=2), "Blacklisted", AND(P41>=100000, Q41>=4, O41<=0.1, V41="Completed"), "Platinum", AND(P41>=50000, P41<=99999, Q41>=3, V41="Completed"), "Gold", AND(Q41<50000, V41="Completed"), "Silver", V41="Pending", "Pending")} -> Blacklisted
A42: ORD10041 | B42: C007 | C42: P301 | D42: 10/02/2026 | E42: 12/02/2026 | F42: Arjun Rao | G42: Male | H42: 06/06/1994 | I42: Bengaluru | J42: South | K42: Stationery | L42: Notebook | M42: 8 | N42: 60 | O42: 15 | P42: 408 | Q42: 5 | R42: UPI | S42: Rahul | T42: arjun.rao@company.com | U42: 9276319484 | V42: Pending | W42: {=_xlfn.IFS(OR(V42="Cancelled", Q42<=2), "Blacklisted", AND(P42>=100000, Q42>=4, O42<=0.1, V42="Completed"), "Platinum", AND(P42>=50000, P42<=99999, Q42>=3, V42="Completed"), "Gold", AND(Q42<50000, V42="Completed"), "Silver", V42="Pending", "Pending")} -> Pending
A43: ORD10042 | B43: C010 | C43: P201 | D43: 04/06/2025 | E43: 16/06/2025 | F43: Pooja Shah | G43: Female | H43: 22/09/1988 | I43: Pune | J43: West | K43: Home Appliances | L43: Mixer | M43: 8 | N43: 3500 | O43: 5 | P43: 26600 | Q43: 1 | R43: Card | S43: Neha | T43: pooja.shah@company.com | U43: 9619034852 | V43: Pending | W43: {=_xlfn.IFS(OR(V43="Cancelled", Q43<=2), "Blacklisted", AND(P43>=100000, Q43>=4, O43<=0.1, V43="Completed"), "Platinum", AND(P43>=50000, P43<=99999, Q43>=3, V43="Completed"), "Gold", AND(Q43<50000, V43="Completed"), "Silver", V43="Pending", "Pending")} -> Blacklisted
A44: ORD10043 | B44: C009 | C44: P203 | D44: 08/02/2026 | E44: 14/02/2026 | F44: Mohit Verma | G44: Male | H44: 14/07/2001 | I44: Jaipur | J44: North | K44: Home Appliances | L44: Microwave | M44: 1 | N44: 8500 | O44: 0 | P44: 8500 | Q44: 2 | R44: Card | S44: Neha | T44: mohit.verma@company.com | U44: 9636416962 | V44: Pending | W44: {=_xlfn.IFS(OR(V44="Cancelled", Q44<=2), "Blacklisted", AND(P44>=100000, Q44>=4, O44<=0.1, V44="Completed"), "Platinum", AND(P44>=50000, P44<=99999, Q44>=3, V44="Completed"), "Gold", AND(Q44<50000, V44="Completed"), "Silver", V44="Pending", "Pending")} -> Blacklisted
A45: ORD10044 | B45: C001 | C45: P303 | D45: 30/03/2025 | E45: 31/03/2025 | F45: Amit Sharma | G45: Male | H45: 09/08/1991 | I45: Pune | J45: West | K45: Stationery | L45: Marker | M45: 8 | N45: 45 | O45: 15 | P45: 306 | Q45: 2 | R45: Card | S45: Aisha | T45: amit.sharma@company.com | U45: 9357133880 | V45: Completed | W45: {=_xlfn.IFS(OR(V45="Cancelled", Q45<=2), "Blacklisted", AND(P45>=100000, Q45>=4, O45<=0.1, V45="Completed"), "Platinum", AND(P45>=50000, P45<=99999, Q45>=3, V45="Completed"), "Gold", AND(Q45<50000, V45="Completed"), "Silver", V45="Pending", "Pending")} -> Blacklisted
A46: ORD10045 | B46: C006 | C46: P202 | D46: 25/04/2025 | E46: 28/04/2025 | F46: Sneha Joshi | G46: Female | H46: 21/10/1988 | I46: Pune | J46: West | K46: Home Appliances | L46: Iron | M46: 16 | N46: 2200 | O46: 5 | P46: 33440 | Q46: 5 | R46: Card | S46: Aisha | T46: sneha.joshi@company.com | U46: 9575210324 | V46: Cancelled | W46: {=_xlfn.IFS(OR(V46="Cancelled", Q46<=2), "Blacklisted", AND(P46>=100000, Q46>=4, O46<=0.1, V46="Completed"), "Platinum", AND(P46>=50000, P46<=99999, Q46>=3, V46="Completed"), "Gold", AND(Q46<50000, V46="Completed"), "Silver", V46="Pending", "Pending")} -> Blacklisted
A47: ORD10046 | B47: C009 | C47: P201 | D47: 13/10/2025 | E47: 23/10/2025 | F47: Mohit Verma | G47: Male | H47: 19/11/2002 | I47: Bengaluru | J47: South | K47: Home Appliances | L47: Mixer | M47: 19 | N47: 3500 | O47: 20 | P47: 53200 | Q47: 3 | R47: Cash | S47: Karan | T47: mohit.verma@company.com | U47: 9276080204 | V47: Cancelled | W47: {=_xlfn.IFS(OR(V47="Cancelled", Q47<=2), "Blacklisted", AND(P47>=100000, Q47>=4, O47<=0.1, V47="Completed"), "Platinum", AND(P47>=50000, P47<=99999, Q47>=3, V47="Completed"), "Gold", AND(Q47<50000, V47="Completed"), "Silver", V47="Pending", "Pending")} -> Blacklisted
A48: ORD10047 | B48: C006 | C48: P102 | D48: 11/10/2025 | E48: 14/10/2025 | F48: Sneha Joshi | G48: Female | H48: 06/07/2000 | I48: Pune | J48: West | K48: Electronics | L48: Mouse | M48: 15 | N48: 700 | O48: 15 | P48: 8925 | Q48: 4 | R48: UPI | S48: Neha | T48: sneha.joshicompany.com | U48: 9856624471 | V48: Completed | W48: {=_xlfn.IFS(OR(V48="Cancelled", Q48<=2), "Blacklisted", AND(P48>=100000, Q48>=4, O48<=0.1, V48="Completed"), "Platinum", AND(P48>=50000, P48<=99999, Q48>=3, V48="Completed"), "Gold", AND(Q48<50000, V48="Completed"), "Silver", V48="Pending", "Pending")} -> Silver
A49: ORD10048 | B49: C006 | C49: P102 | D49: 27/11/2025 | E49: 03/12/2025 | F49: Sneha Joshi | G49: Female | H49: 26/11/1998 | I49: Jaipur | J49: North | K49: Electronics | L49: Mouse | M49: 19 | N49: 700 | O49: 20 | P49: 10640 | Q49: 1 | R49: Cash | S49: Neha | T49: sneha.joshi@company.com | U49: 9238141322 | V49: Completed | W49: {=_xlfn.IFS(OR(V49="Cancelled", Q49<=2), "Blacklisted", AND(P49>=100000, Q49>=4, O49<=0.1, V49="Completed"), "Platinum", AND(P49>=50000, P49<=99999, Q49>=3, V49="Completed"), "Gold", AND(Q49<50000, V49="Completed"), "Silver", V49="Pending", "Pending")} -> Blacklisted
A50: ORD10049 | B50: C009 | C50: P104 | D50: 19/04/2026 | E50: Not Available | F50: Mohit Verma | G50: Male | H50: 03/06/1996 | I50: Delhi | J50: North | K50: Electronics | L50: Monitor | M50: 19 | N50: 12000 | O50: 0 | P50: 228000 | Q50: 1 | R50: NetBanking | S50: Aisha | T50: mohit.verma@company.com | U50: 9890380030 | V50: Completed | W50: {=_xlfn.IFS(OR(V50="Cancelled", Q50<=2), "Blacklisted", AND(P50>=100000, Q50>=4, O50<=0.1, V50="Completed"), "Platinum", AND(P50>=50000, P50<=99999, Q50>=3, V50="Completed"), "Gold", AND(Q50<50000, V50="Completed"), "Silver", V50="Pending", "Pending")} -> Blacklisted
A51: ORD10050 | B51: C004 | C51: P103 | D51: 19/04/2026 | E51: 21/04/2026 | F51: Anita Gupta | G51: Female | H51: 15/03/1987 | I51: Pune | J51: West | K51: Electronics | L51: Keyboard | M51: 6 | N51: 1200 | O51: 5 | P51: 6840 | Q51: 2 | R51: Cash | S51: Ritika | T51: anita.gupta@company.com | U51: 9495893170 | V51: Pending | W51: {=_xlfn.IFS(OR(V51="Cancelled", Q51<=2), "Blacklisted", AND(P51>=100000, Q51>=4, O51<=0.1, V51="Completed"), "Platinum", AND(P51>=50000, P51<=99999, Q51>=3, V51="Completed"), "Gold", AND(Q51<50000, V51="Completed"), "Silver", V51="Pending", "Pending")} -> Blacklisted
A52: ORD10051 | B52: C010 | C52: P202 | D52: 28/03/2025 | E52: 07/04/2025 | F52: Pooja Shah | G52: Female | H52: 20/02/1979 | I52: Bengaluru | J52: South | K52: Home Appliances | L52: Iron | M52: 7 | N52: 2200 | O52: 15 | P52: 13090 | Q52: 1 | R52: UPI | S52: Aisha | T52: pooja.shah@company.com | U52: 9485166307 | V52: Completed | W52: {=_xlfn.IFS(OR(V52="Cancelled", Q52<=2), "Blacklisted", AND(P52>=100000, Q52>=4, O52<=0.1, V52="Completed"), "Platinum", AND(P52>=50000, P52<=99999, Q52>=3, V52="Completed"), "Gold", AND(Q52<50000, V52="Completed"), "Silver", V52="Pending", "Pending")} -> Blacklisted
... A501: ORD10500 | B501: C002 | C501: P201 | D501: 16/09/2025 | E501: 23/09/2025 | F501: Priya Patel | G501: Female | H501: 24/11/1976 | I501: Bengaluru | J501: South | K501: Home Appliances | L501: Mixer | M501: 20 | N501: 3500 | O501: 0 | P501: 70000 | Q501: 1 | R501: NetBanking | S501: Karan | T501: priya.patel@company.com | U501: 9810334941 | V501: Pending | W501: {=_xlfn.IFS(OR(V501="Cancelled", Q501<=2), "Blacklisted", AND(P501>=100000, Q501>=4, O501<=0.1, V501="Completed"), "Platinum", AND(P501>=50000, P501<=99999, Q501>=3, V501="Completed"), "Gold", AND(Q501<50000, V501="Completed"), "Silver", V501="Pending", "Pending")} -> Blacklisted

Sheet Q2
A1: Order_ID | B1: Customer_ID | C1: Product_ID | D1: Order_Date | E1: Delivery_Date | F1: Customer_Name | G1: Gender | H1: DOB | I1: City | J1: Region | K1: Category | L1: Product_Name | M1: Quantity | N1: Unit_Price | O1: Discount_% | P1: Sales | Q1: Rating | R1: Payment_Mode | S1: Salesperson | T1: Email | U1: Phone | V1: Order_Status | W1: Customer Code
A2: ORD10001 | B2: C008 | C2: P202 | D2: 18/09/2025 | E2: 22/09/2025 | F2: Kavya Nair | G2: Female | H2: 01/08/1976 | I2: Hyderabad | J2: South | K2: Home Appliances | L2: Iron | M2: 4 | N2: 2200 | O2: 10 | P2: 7920 | Q2: 4 | R2: Cash | S2: Ritika | T2: kavya.nair@company.com | U2: 9431429797 | V2: Completed | W2: =LEFT(F2, 3) & RIGHT(B2,3) & LEFT(I2,2) -> Kav008Hy
A3: ORD10002 | B3: C008 | C3: P104 | D3: 27/04/2025 | E3: 04/05/2025 | F3: Kavya Nair | G3: Female | H3: 16/10/2000 | I3: Delhi | J3: North | K3: Electronics | L3: Monitor | M3: 17 | N3: 12000 | O3: 10 | P3: 183600 | Q3: 1 | R3: NetBanking | S3: Rahul | T3: kavya.nair@company.com | U3: 9129865339 | V3: Completed | W3: =LEFT(F3, 3) & RIGHT(B3,3) & LEFT(I3,2) -> Kav008De
A4: ORD10003 | B4: C010 | C4: P101 | D4: 03/09/2025 | E4: 14/09/2025 | F4: Pooja Shah | G4: Female | H4: 16/09/1994 | I4: Bengaluru | J4: South | K4: Electronics | L4: Laptop | M4: 5 | N4: 55000 | O4: 5 | P4: 261250 | Q4: 3 | R4: NetBanking | S4: Aisha | T4: pooja.shah@company.com | U4: 9380975626 | V4: Pending | W4: =LEFT(F4, 3) & RIGHT(B4,3) & LEFT(I4,2) -> Poo010Be
A5: ORD10002 | B5: C008 | C5: P202 | D5: 21/03/2026 | E5: 02/04/2026 | F5: Kavya Nair | G5: Female | H5: 07/03/2004 | I5: Bengaluru | J5: South | K5: Home Appliances | L5: Iron | M5: 5 | N5: 2200 | O5: 5 | P5: 10450 | Q5: 5 | R5: NetBanking | S5: Aisha | T5: kavya.nair@company.com | U5: 9600261125 | V5: Cancelled | W5: =LEFT(F5, 3) & RIGHT(B5,3) & LEFT(I5,2) -> Kav008Be
A6: ORD10005 | B6: C009 | C6: P103 | D6: 27/09/2025 | E6: 07/10/2025 | F6: Mohit Verma | G6: Male | H6: 13/04/1976 | I6: Delhi | J6: North | K6: Electronics | L6: Keyboard | M6: 8 | N6: 1200 | O6: 5 | P6: 9120 | Q6: 2 | R6: Card | S6: Aisha | T6: mohit.verma@company.com | U6: 9724635978 | V6: Pending | W6: =LEFT(F6, 3) & RIGHT(B6,3) & LEFT(I6,2) -> Moh009De
A7: ORD10006 | B7: C007 | C7: P202 | D7: 04/01/2026 | E7: 12/01/2026 | F7: Arjun Rao | G7: Male | H7: 07/02/1988 | I7: Hyderabad | J7: South | K7: Home Appliances | L7: Iron | M7: 4 | N7: 2200 | O7: 0 | P7: 8800 | Q7: 1 | R7: UPI | S7: Ritika | T7: arjun.rao@company.com | U7: 9780584905 | V7: Completed | W7: =LEFT(F7, 3) & RIGHT(B7,3) & LEFT(I7,2) -> Arj007Hy
A8: ORD10007 | B8: C008 | C8: P201 | D8: 31/02/2025 | E8: 25/02/2026 | F8: Kavya Nair | G8: Female | H8: 20/03/2003 | I8: Hyderabad | J8: South | K8: Home Appliances | L8: Mixer | M8: 2 | N8: 3500 | O8: 5 | P8: 6650 | Q8: 1 | R8: UPI | S8: Ritika | T8: kavya.nair@company.com | U8: 9958252176 | V8: Completed | W8: =LEFT(F8, 3) & RIGHT(B8,3) & LEFT(I8,2) -> Kav008Hy
A9: ORD10008 | B9: C002 | C9: P104 | D9: 13/04/2025 | E9: 19/04/2025 | F9: Priya Patel | G9: Female | H9: 07/03/1995 | I9: Mumbai | J9: West | K9: Electronics | L9: Monitor | M9: 14 | N9: 12000 | O9: 15 | P9: 142800 | Q9: 4 | R9: NetBanking | S9: Ritika | T9: priya.patel@company.com | U9: 9705521654 | V9: Completed | W9: =LEFT(F9, 3) & RIGHT(B9,3) & LEFT(I9,2) -> Pri002Mu
A10: ORD10009 | B10: C008 | C10: P104 | D10: 31/01/2026 | E10: 02/02/2026 | F10: Kavya Nair | G10: Female | H10: 06/04/1997 | I10: Pune | J10: West | K10: Electronics | L10: Monitor | M10: 4 | N10: 12000 | O10: 15 | P10: 40800 | Q10: 4 | R10: UPI | S10: Neha | T10: kavya.nair@company.com | U10: 9588041011 | V10: Completed | W10: =LEFT(F10, 3) & RIGHT(B10,3) & LEFT(I10,2) -> Kav008Pu
A11: ORD10010 | B11: C002 | C11: P301 | D11: 25/03/2025 | E11: 27/03/2025 | F11: Priya Patel | G11: Female | H11: 07/01/1990 | I11: Mumbai | J11: West | K11: Stationery | L11: Notebook | M11: 6 | N11: 60 | O11: 0 | P11: 360 | Q11: 4 | R11: Card | S11: Neha | T11: priya.patel@company.com | U11: 9340540608 | V11: Completed | W11: =LEFT(F11, 3) & RIGHT(B11,3) & LEFT(I11,2) -> Pri002Mu
A12: ORD10011 | B12: C003 | C12: P202 | D12: 19/09/2025 | E12: 23/09/2025 | F12: Rohit Singh | G12: Male | H12: 10/05/1982 | I12: Delhi | J12: North | K12: Home Appliances | L12: Iron | M12: -3 | N12: 2200 | O12: 0 | P12: 35200 | Q12: 2 | R12: Card | S12: Rahul | T12: rohit.singh@company.com | U12: 9521710321 | V12: Pending | W12: =LEFT(F12, 3) & RIGHT(B12,3) & LEFT(I12,2) -> Roh003De
A13: ORD10012 | B13: C008 | C13: P201 | D13: 08/03/2025 | E13: 15/03/2025 | F13: Kavya Nair | G13: Female | H13: 23/01/1982 | I13: Ahmedabad | J13: West | K13: Home Appliances | L13: Mixer | M13: 10 | N13: 3500 | O13: 5 | P13: 33250 | Q13: 5 | R13: Card | S13: Aisha | T13: kavya.nair@company.com | U13: 9123535241 | V13: Cancelled | W13: =LEFT(F13, 3) & RIGHT(B13,3) & LEFT(I13,2) -> Kav008Ah
... A39: ORD10038 | B39: C006 | C39: P201 | D39: 08/03/2026 | E39: 20/03/2026 | F39: Sneha Joshi | G39: Female | H39: 21/06/1980 | I39: Delhi | J39: North | K39: Home Appliances | L39: Mixer | M39: 20 | N39: 3500 | O39: 10 | P39: 63000 | Q39: 3 | R39: Card | S39: Rahul | T39: sneha.joshi@company.com | U39: 9283578533 | V39: Cancelled | W39: =LEFT(F39, 3) & RIGHT(B39,3) & LEFT(I39,2) -> Sne006De
A40: ORD10039 | B40: C008 | C40: P302 | D40: 13/02/2025 | E40: 19/02/2025 | F40: Kavya Nair | G40: Female | H40: 17/06/1979 | I40: Pune | J40: West | K40: Stationery | L40: Pen | M40: 5 | N40: 1200 | O40: 0 | P40: 100 | Q40: 1 | R40: Cash | S40: Rahul | T40: kavya.nair@company.com | U40: 9963005771 | V40: Cancelled | W40: =LEFT(F40, 3) & RIGHT(B40,3) & LEFT(I40,2) -> Kav008Pu
A41: ORD10040 | B41: C010 | C41: P203 | D41: 05/10/2025 | E41: 15/10/2025 | F41: Pooja Shah | G41: Female | H41: 18/06/1992 | I41: Mumbai | J41: West | K41: Home Appliances | L41: Microwave | M41: 20 | N41: 8500 | O41: 0 | P41: 170000 | Q41: 1 | R41: UPI | S41: Neha | T41: pooja.shah@company.com | U41: 9484632635 | V41: Cancelled | W41: =LEFT(F41, 3) & RIGHT(B41,3) & LEFT(I41,2) -> Poo010Mu
A42: ORD10041 | B42: C007 | C42: P301 | D42: 10/02/2026 | E42: 12/02/2026 | F42: Arjun Rao | G42: Male | H42: 06/06/1994 | I42: Bengaluru | J42: South | K42: Stationery | L42: Notebook | M42: 8 | N42: 60 | O42: 15 | P42: 408 | Q42: 5 | R42: UPI | S42: Rahul | T42: arjun.rao@company.com | U42: 9276319484 | V42: Pending | W42: =LEFT(F42, 3) & RIGHT(B42,3) & LEFT(I42,2) -> Arj007Be
A43: ORD10042 | B43: C010 | C43: P201 | D43: 04/06/2025 | E43: 16/06/2025 | F43: Pooja Shah | G43: Female | H43: 22/09/1988 | I43: Pune | J43: West | K43: Home Appliances | L43: Mixer | M43: 8 | N43: 3500 | O43: 5 | P43: 26600 | Q43: 1 | R43: Card | S43: Neha | T43: pooja.shah@company.com | U43: 9619034852 | V43: Pending | W43: =LEFT(F43, 3) & RIGHT(B43,3) & LEFT(I43,2) -> Poo010Pu
A44: ORD10043 | B44: C009 | C44: P203 | D44: 08/02/2026 | E44: 14/02/2026 | F44: Mohit Verma | G44: Male | H44: 14/07/2001 | I44: Jaipur | J44: North | K44: Home Appliances | L44: Microwave | M44: 1 | N44: 8500 | O44: 0 | P44: 8500 | Q44: 2 | R44: Card | S44: Neha | T44: mohit.verma@company.com | U44: 9636416962 | V44: Pending | W44: =LEFT(F44, 3) & RIGHT(B44,3) & LEFT(I44,2) -> Moh009Ja
A45: ORD10044 | B45: C001 | C45: P303 | D45: 30/03/2025 | E45: 31/03/2025 | F45: Amit Sharma | G45: Male | H45: 09/08/1991 | I45: Pune | J45: West | K45: Stationery | L45: Marker | M45: 8 | N45: 45 | O45: 15 | P45: 306 | Q45: 2 | R45: Card | S45: Aisha | T45: amit.sharma@company.com | U45: 9357133880 | V45: Completed | W45: =LEFT(F45, 3) & RIGHT(B45,3) & LEFT(I45,2) -> Ami001Pu
A46: ORD10045 | B46: C006 | C46: P202 | D46: 25/04/2025 | E46: 28/04/2025 | F46: Sneha Joshi | G46: Female | H46: 21/10/1988 | I46: Pune | J46: West | K46: Home Appliances | L46: Iron | M46: 16 | N46: 2200 | O46: 5 | P46: 33440 | Q46: 5 | R46: Card | S46: Aisha | T46: sneha.joshi@company.com | U46: 9575210324 | V46: Cancelled | W46: =LEFT(F46, 3) & RIGHT(B46,3) & LEFT(I46,2) -> Sne006Pu
A47: ORD10046 | B47: C009 | C47: P201 | D47: 13/10/2025 | E47: 23/10/2025 | F47: Mohit Verma | G47: Male | H47: 19/11/2002 | I47: Bengaluru | J47: South | K47: Home Appliances | L47: Mixer | M47: 19 | N47: 3500 | O47: 20 | P47: 53200 | Q47: 3 | R47: Cash | S47: Karan | T47: mohit.verma@company.com | U47: 9276080204 | V47: Cancelled | W47: =LEFT(F47, 3) & RIGHT(B47,3) & LEFT(I47,2) -> Moh009Be
A48: ORD10047 | B48: C006 | C48: P102 | D48: 11/10/2025 | E48: 14/10/2025 | F48: Sneha Joshi | G48: Female | H48: 06/07/2000 | I48: Pune | J48: West | K48: Electronics | L48: Mouse | M48: 15 | N48: 700 | O48: 15 | P48: 8925 | Q48: 4 | R48: UPI | S48: Neha | T48: Invalid Email | U48: 9856624471 | V48: Completed | W48: =LEFT(F48, 3) & RIGHT(B48,3) & LEFT(I48,2) -> Sne006Pu
A49: ORD10048 | B49: C006 | C49: P102 | D49: 27/11/2025 | E49: 03/12/2025 | F49: Sneha Joshi | G49: Female | H49: 26/11/1998 | I49: Jaipur | J49: North | K49: Electronics | L49: Mouse | M49: 19 | N49: 700 | O49: 20 | P49: 10640 | Q49: 1 | R49: Cash | S49: Neha | T49: sneha.joshi@company.com | U49: 9238141322 | V49: Completed | W49: =LEFT(F49, 3) & RIGHT(B49,3) & LEFT(I49,2) -> Sne006Ja
A50: ORD10049 | B50: C009 | C50: P104 | D50: 19/04/2026 | E50: Not Available | F50: Mohit Verma | G50: Male | H50: 03/06/1996 | I50: Delhi | J50: North | K50: Electronics | L50: Monitor | M50: 19 | N50: 12000 | O50: 0 | P50: 228000 | Q50: 1 | R50: NetBanking | S50: Aisha | T50: mohit.verma@company.com | U50: 9890380030 | V50: Completed | W50: =LEFT(F50, 3) & RIGHT(B50,3) & LEFT(I50,2) -> Moh009De
A51: ORD10050 | B51: C004 | C51: P103 | D51: 19/04/2026 | E51: 21/04/2026 | F51: Anita Gupta | G51: Female | H51: 15/03/1987 | I51: Pune | J51: West | K51: Electronics | L51: Keyboard | M51: 6 | N51: 1200 | O51: 5 | P51: 6840 | Q51: 2 | R51: Cash | S51: Ritika | T51: anita.gupta@company.com | U51: 9495893170 | V51: Pending | W51: =LEFT(F51, 3) & RIGHT(B51,3) & LEFT(I51,2) -> Ani004Pu
A52: ORD10051 | B52: C010 | C52: P202 | D52: 28/03/2025 | E52: 07/04/2025 | F52: Pooja Shah | G52: Female | H52: 20/02/1979 | I52: Bengaluru | J52: South | K52: Home Appliances | L52: Iron | M52: 7 | N52: 2200 | O52: 15 | P52: 13090 | Q52: 1 | R52: UPI | S52: Aisha | T52: pooja.shah@company.com | U52: 9485166307 | V52: Completed | W52: =LEFT(F52, 3) & RIGHT(B52,3) & LEFT(I52,2) -> Poo010Be
... A119: ORD10118 | B119: C001 | C119: P303 | D119: 31/05/2025 | E119: 11/06/2025 | F119: Amit Sharma | G119: Male | H119: 07/09/1995 | I119: Pune | J119: West | K119: Stationery | L119: Marker | M119: 16 | N119: 45 | O119: 0 | P119: 720 | Q119: 1 | R119: NetBanking | S119: Aisha | T119: amit.sharma@company.com | U119: 9807154421 | V119: Completed | W119: =LEFT(F119, 3) & RIGHT(B119,3) & LEFT(I119,2) -> Ami001Pu
A120: ORD10119 | B120: C009 | C120: P103 | D120: 30/05/2025 | E120: 02/06/2025 | F120: Mohit Verma | G120: Male | H120: 08/03/1988 | I120: Ahmedabad | J120: West | K120: Electronics | L120: Keyboard | M120: Ten | N120: 1200 | O120: 15 | P120: 7140 | Q120: 4 | R120: UPI | S120: Karan | T120: mohit.verma@company.com | U120: 9919834000 | V120: Pending | W120: =LEFT(F120, 3) & RIGHT(B120,3) & LEFT(I120,2) -> Moh009Ah
A121: ORD10120 | B121: C002 | C121: P104 | D121: 19/08/2025 | E121: 30/08/2025 | F121: Priya Patel | G121: Female | H121: 07/07/1989 | I121: Jaipur | J121: North | K121: Electronics | L121: Monitor | M121: 14 | N121: 12000 | O121: 15 | P121: 142800 | Q121: 2 | R121: NetBanking | S121: Aisha | T121: priya.patel@company.com | U121: 9739798818 | V121: Pending | W121: =LEFT(F121, 3) & RIGHT(B121,3) & LEFT(I121,2) -> Pri002Ja
A122: ORD10121 | B122: C003 | C122: P203 | D122: 14/12/2025 | E122: 16/12/2025 | F122: Rohit Singh | G122: Male | H122: 11/11/1993 | I122: Pune | J122: West | K122: Home Appliances | L122: Microwave | M122: 8 | N122: 8500 | O122: 20 | P122: 54400 | Q122: 3 | R122: Card | S122: Rahul | T122: rohit.singh@company.com | U122: 9208625306 | V122: Completed | W122: =LEFT(F122, 3) & RIGHT(B122,3) & LEFT(I122,2) -> Roh003Pu
A123: ORD10122 | B123: C007 | C123: P303 | D123: 31/01/2026 | E123: 10/02/2026 | F123: Arjun Rao | G123: Male | H123: 01/02/2000 | I123: Bengaluru | J123: South | K123: Stationery | L123: Marker | M123: 3 | N123: 45 | O123: 0 | P123: 135 | Q123: 4 | R123: UPI | S123: Aisha | T123: arjun.rao@company.com | U123: 9970178536 | V123: Cancelled | W123: =LEFT(F123, 3) & RIGHT(B123,3) & LEFT(I123,2) -> Arj007Be
A124: ORD10123 | B124: C001 | C124: P102 | D124: 03/01/2026 | E124: 04/01/2026 | F124: Amit Sharma | G124: Male | H124: 22/06/1986 | I124: Jaipur | J124: North | K124: Electronics | L124: Mouse | M124: 13 | N124: 700 | O124: 5 | P124: 8645 | Q124: 3 | R124: Card | S124: Neha | T124: amit.sharma@company.com | U124: 9633745195 | V124: Pending | W124: =LEFT(F124, 3) & RIGHT(B124,3) & LEFT(I124,2) -> Ami001Ja
A125: ORD10124 | B125: C004 | C125: P103 | D125: 20/10/2025 | E125: 26/10/2025 | F125: Anita Gupta | G125: Female | H125: 16/02/1986 | I125: Mumbai | J125: West | K125: Electronics | L125: Keyboard | M125: 14 | N125: 1200 | O125: 20 | P125: 13440 | Q125: 5 | R125: NetBanking | S125: Aisha | T125: anita.gupta@company.com | U125: 9922102053 | V125: Completed | W125: =LEFT(F125, 3) & RIGHT(B125,3) & LEFT(I125,2) -> Ani004Mu
A126: ORD10125 | B126: C002 | C126: P303 | D126: 11/05/2025 | E126: 21/05/2025 | F126: Priya Patel | G126: Female | H126: 18/09/1991 | I126: Delhi | J126: North | K126: Stationery | L126: Marker | M126: 2 | N126: 45 | O126: 5 | P126: 85.5 | Q126: 3 | R126: UPI | S126: Ritika | T126: priya.patel@company.com | U126: 9135963930 | V126: Cancelled | W126: =LEFT(F126, 3) & RIGHT(B126,3) & LEFT(I126,2) -> Pri002De
A127: ORD10126 | B127: C004 | C127: P103 | D127: 02/01/2026 | E127: 06/01/2026 | F127: Anita Gupta | G127: Female | H127: 04/01/1981 | I127: Bengaluru | J127: South | K127: Electronics | L127: Keyboard | M127: 2 | N127: 1200 | O127: 20 | P127: 1920 | Q127: 3 | R127: Card | S127: Neha | T127: anita.gupta@company.com | U127: 9429405275 | V127: Completed | W127: =LEFT(F127, 3) & RIGHT(B127,3) & LEFT(I127,2) -> Ani004Be
A128: ORD10127 | B128: C003 | C128: P101 | D128: 20/04/2026 | E128: 26/04/2026 | F128: Rohit Singh | G128: Male | H128: 12/10/2004 | I128: Bengaluru | J128: South | K128: Electronics | L128: Laptop | M128: 10 | N128: 55000 | O128: 5 | P128: 522500 | Q128: 5 | R128: UPI | S128: Aisha | T128: rohit.singh@company.com | U128: 9521757571 | V128: Pending | W128: =LEFT(F128, 3) & RIGHT(B128,3) & LEFT(I128,2) -> Roh003Be
A129: ORD10128 | B129: C006 | C129: P201 | D129: 04/08/2025 | E129: 05/08/2025 | F129: Sneha Joshi | G129: Female | H129: 25/03/1984 | I129: Jaipur | J129: North | K129: Home Appliances | L129: Mixer | M129: 15 | N129: 3500 | O129: 10 | P129: 47250 | Q129: 3 | R129: NetBanking | S129: Neha | T129: sneha.joshi@company.com | U129: 9467375455 | V129: Completed | W129: =LEFT(F129, 3) & RIGHT(B129,3) & LEFT(I129,2) -> Sne006Ja
A130: ORD10129 | B130: C002 | C130: P202 | D130: 13/08/2025 | E130: 18/08/2025 | F130: Priya Patel | G130: Female | H130: 09/09/1982 | I130: Bengaluru | J130: South | K130: Home Appliances | L130: Iron | M130: 10 | N130: 2200 | O130: 15 | P130: 18700 | Q130: 4 | R130: Card | S130: Rahul | T130: priya.patel@company.com | U130: 9838809695 | V130: Pending | W130: =LEFT(F130, 3) & RIGHT(B130,3) & LEFT(I130,2) -> Pri002Be
A131: ORD10130 | B131: C006 | C131: P201 | D131: 16/06/2025 | E131: 24/06/2025 | F131: Sneha Joshi | G131: Female | H131: 15/02/1993 | I131: Pune | J131: West | K131: Home Appliances | L131: Mixer | M131: 11 | N131: 3500 | O131: 5 | P131: 36575 | Q131: 5 | R131: Cash | S131: Ritika | T131: sneha.joshi@company.com | U131: 9296609782 | V131: Cancelled | W131: =LEFT(F131, 3) & RIGHT(B131,3) & LEFT(I131,2) -> Sne006Pu
...

Sheet Q3
A1: Order_ID | B1: Customer_ID | C1: Product_ID | D1: Order_Date | E1: Delivery_Date | F1: Customer_Name | G1: Gender | H1: DOB | I1: City | J1: Region | K1: Category | L1: Product_Name | M1: Quantity | N1: Unit_Price | O1: Discount_% | P1: Sales | Q1: Rating | R1: Payment_Mode | S1: Salesperson | T1: Email | U1: Phone | V1: Order_Status | W1: Customer Age | X1: Delivery Time (Days) | Y1: Delivery Status
A2: ORD10001 | B2: C008 | C2: P202 | D2: 45918 | E2: 45922 | F2: Kavya Nair | G2: Female | H2: 27973 | I2: Hyderabad | J2: South | K2: Home Appliances | L2: Iron | M2: 4 | N2: 2200 | O2: 10 | P2: 7920 | Q2: 4 | R2: Cash | S2: Ritika | T2: kavya.nair@company.com | U2: 9431429797 | V2: Completed | W2: =DATEDIF(H2, TODAY(), "y") -> 50 | X2: =IF(OR(ISBLANK(D2), ISBLANK(E2)), "Not Available", E2-D2) -> 4 | Y2: =IF(ISBLANK(E2), "Pending", IF(E2-D2<=5, "On Time ", "Delayed")) -> On Time
A3: ORD10002 | B3: C008 | C3: P104 | D3: 45774 | E3: 45781 | F3: Kavya Nair | G3: Female | H3: 36815 | I3: Delhi | J3: North | K3: Electronics | L3: Monitor | M3: 17 | N3: 12000 | O3: 10 | P3: 183600 | Q3: 1 | R3: NetBanking | S3: Rahul | T3: kavya.nair@company.com | U3: 9129865339 | V3: Completed | W3: =DATEDIF(H3, TODAY(), "y") -> 25 | X3: =IF(OR(ISBLANK(D3), ISBLANK(E3)), "Not Available", E3-D3) -> 7 | Y3: =IF(ISBLANK(E3), "Pending", IF(E3-D3<=5, "On Time ", "Delayed")) -> Delayed
A4: ORD10003 | B4: C010 | C4: P101 | D4: 45903 | E4: 45914 | F4: Pooja Shah | G4: Female | H4: 34593 | I4: Bengaluru | J4: South | K4: Electronics | L4: Laptop | M4: 5 | N4: 55000 | O4: 5 | P4: 261250 | Q4: 3 | R4: NetBanking | S4: Aisha | T4: pooja.shah@company.com | U4: 9380975626 | V4: Pending | W4: =DATEDIF(H4, TODAY(), "y") -> 32 | X4: =IF(OR(ISBLANK(D4), ISBLANK(E4)), "Not Available", E4-D4) -> 11 | Y4: =IF(ISBLANK(E4), "Pending", IF(E4-D4<=5, "On Time ", "Delayed")) -> Delayed
A5: ORD10002 | B5: C008 | C5: P202 | D5: 46102 | E5: 46114 | F5: Kavya Nair | G5: Female | H5: 38053 | I5: Bengaluru | J5: South | K5: Home Appliances | L5: Iron | M5: 5 | N5: 2200 | O5: 5 | P5: 10450 | Q5: 5 | R5: NetBanking | S5: Aisha | T5: kavya.nair@company.com | U5: 9600261125 | V5: Cancelled | W5: =DATEDIF(H5, TODAY(), "y") -> 22 | X5: =IF(OR(ISBLANK(D5), ISBLANK(E5)), "Not Available", E5-D5) -> 12 | Y5: =IF(ISBLANK(E5), "Pending", IF(E5-D5<=5, "On Time ", "Delayed")) -> Delayed
A6: ORD10005 | B6: C009 | C6: P103 | D6: 45927 | E6: 45937 | F6: Mohit Verma | G6: Male | H6: 27863 | I6: Delhi | J6: North | K6: Electronics | L6: Keyboard | M6: 8 | N6: 1200 | O6: 5 | P6: 9120 | Q6: 2 | R6: Card | S6: Aisha | T6: mohit.verma@company.com | U6: 9724635978 | V6: Pending | W6: =DATEDIF(H6, TODAY(), "y") -> 50 | X6: =IF(OR(ISBLANK(D6), ISBLANK(E6)), "Not Available", E6-D6) -> 10 | Y6: =IF(ISBLANK(E6), "Pending", IF(E6-D6<=5, "On Time ", "Delayed")) -> Delayed
A7: ORD10006 | B7: C007 | C7: P202 | D7: 46026 | E7: 46034 | F7: Arjun Rao | G7: Male | H7: 32180 | I7: Hyderabad | J7: South | K7: Home Appliances | L7: Iron | M7: 4 | N7: 2200 | O7: 0 | P7: 8800 | Q7: 1 | R7: UPI | S7: Ritika | T7: arjun.rao@company.com | U7: 9780584905 | V7: Completed | W7: =DATEDIF(H7, TODAY(), "y") -> 38 | X7: =IF(OR(ISBLANK(D7), ISBLANK(E7)), "Not Available", E7-D7) -> 8 | Y7: =IF(ISBLANK(E7), "Pending", IF(E7-D7<=5, "On Time ", "Delayed")) -> Delayed
A8: ORD10007 | B8: C008 | C8: P201 | E8: 46078 | F8: Kavya Nair | G8: Female | H8: 37700 | I8: Hyderabad | J8: South | K8: Home Appliances | L8: Mixer | M8: 2 | N8: 3500 | O8: 5 | P8: 6650 | Q8: 1 | R8: UPI | S8: Ritika | T8: kavya.nair@company.com | U8: 9958252176 | V8: Completed | W8: =DATEDIF(H8, TODAY(), "y") -> 23 | X8: =IF(OR(ISBLANK(D8), ISBLANK(E8)), "Not Available", E8-D8) -> Not Available | Y8: =IF(ISBLANK(E8), "Pending", IF(E8-D8<=5, "On Time ", "Delayed")) -> Delayed
A9: ORD10008 | B9: C002 | C9: P104 | D9: 45760 | E9: 45766 | F9: Priya Patel | G9: Female | H9: 34765 | I9: Mumbai | J9: West | K9: Electronics | L9: Monitor | M9: 14 | N9: 12000 | O9: 15 | P9: 142800 | Q9: 4 | R9: NetBanking | S9: Ritika | T9: priya.patel@company.com | U9: 9705521654 | V9: Completed | W9: =DATEDIF(H9, TODAY(), "y") -> 31 | X9: =IF(OR(ISBLANK(D9), ISBLANK(E9)), "Not Available", E9-D9) -> 6 | Y9: =IF(ISBLANK(E9), "Pending", IF(E9-D9<=5, "On Time ", "Delayed")) -> Delayed
A10: ORD10009 | B10: C008 | C10: P104 | D10: 46053 | E10: 46055 | F10: Kavya Nair | G10: Female | H10: 35526 | I10: Pune | J10: West | K10: Electronics | L10: Monitor | M10: 4 | N10: 12000 | O10: 15 | P10: 40800 | Q10: 4 | R10: UPI | S10: Neha | T10: kavya.nair@company.com | U10: 9588041011 | V10: Completed | W10: =DATEDIF(H10, TODAY(), "y") -> 29 | X10: =IF(OR(ISBLANK(D10), ISBLANK(E10)), "Not Available", E10-D10) -> 2 | Y10: =IF(ISBLANK(E10), "Pending", IF(E10-D10<=5, "On Time ", "Delayed")) -> On Time
A11: ORD10010 | B11: C002 | C11: P301 | D11: 45741 | E11: 45743 | F11: Priya Patel | G11: Female | H11: 32880 | I11: Mumbai | J11: West | K11: Stationery | L11: Notebook | M11: 6 | N11: 60 | O11: 0 | P11: 360 | Q11: 4 | R11: Card | S11: Neha | T11: priya.patel@company.com | U11: 9340540608 | V11: Completed | W11: =DATEDIF(H11, TODAY(), "y") -> 36 | X11: =IF(OR(ISBLANK(D11), ISBLANK(E11)), "Not Available", E11-D11) -> 2 | Y11: =IF(ISBLANK(E11), "Pending", IF(E11-D11<=5, "On Time ", "Delayed")) -> On Time
A12: ORD10011 | B12: C003 | C12: P202 | D12: 45919 | E12: 45923 | F12: Rohit Singh | G12: Male | H12: 30081 | I12: Delhi | J12: North | K12: Home Appliances | L12: Iron | M12: -3 | N12: 2200 | O12: 0 | P12: 35200 | Q12: 2 | R12: Card | S12: Rahul | T12: rohit.singh@company.com | U12: 9521710321 | V12: Pending | W12: =DATEDIF(H12, TODAY(), "y") -> 44 | X12: =IF(OR(ISBLANK(D12), ISBLANK(E12)), "Not Available", E12-D12) -> 4 | Y12: =IF(ISBLANK(E12), "Pending", IF(E12-D12<=5, "On Time ", "Delayed")) -> On Time
A13: ORD10012 | B13: C008 | C13: P201 | D13: 45724 | E13: 45731 | F13: Kavya Nair | G13: Female | H13: 29974 | I13: Ahmedabad | J13: West | K13: Home Appliances | L13: Mixer | M13: 10 | N13: 3500 | O13: 5 | P13: 33250 | Q13: 5 | R13: Card | S13: Aisha | T13: kavya.nair@company.com | U13: 9123535241 | V13: Cancelled | W13: =DATEDIF(H13, TODAY(), "y") -> 44 | X13: =IF(OR(ISBLANK(D13), ISBLANK(E13)), "Not Available", E13-D13) -> 7 | Y13: =IF(ISBLANK(E13), "Pending", IF(E13-D13<=5, "On Time ", "Delayed")) -> Delayed
A14: ORD10013 | B14: C002 | C14: P202 | D14: 45667 | E14: 45672 | F14: Priya Patel | G14: Female | H14: 33791 | I14: Pune | J14: West | K14: Home Appliances | L14: Iron | M14: 15 | N14: 2200 | O14: 10 | P14: 29700 | Q14: 1 | R14: UPI | S14: Neha | T14: priya.patel@company.com | U14: 9367316892 | V14: Pending | W14: =DATEDIF(H14, TODAY(), "y") -> 34 | X14: =IF(OR(ISBLANK(D14), ISBLANK(E14)), "Not Available", E14-D14) -> 5 | Y14: =IF(ISBLANK(E14), "Pending", IF(E14-D14<=5, "On Time ", "Delayed")) -> On Time
A15: ORD10014 | B15: C003 | C15: P202 | D15: 45725 | E15: 45729 | F15: Rohit Singh | G15: Male | H15: 37334 | I15: Mumbai | J15: West | K15: Home Appliances | L15: Iron | M15: 17 | N15: 2200 | O15: 5 | P15: 35530 | Q15: 1 | R15: Cash | S15: Karan | T15: rohit.singh@company.com | U15: 9778489803 | V15: Completed | W15: =DATEDIF(H15, TODAY(), "y") -> 24 | X15: =IF(OR(ISBLANK(D15), ISBLANK(E15)), "Not Available", E15-D15) -> 4 | Y15: =IF(ISBLANK(E15), "Pending", IF(E15-D15<=5, "On Time ", "Delayed")) -> On Time
A16: ORD10015 | B16: C008 | C16: P201 | D16: 45864 | E16: 45876 | F16: Kavya Nair | G16: Female | H16: 36908 | I16: Mumbai | J16: West | K16: Home Appliances | L16: Mixer | M16: 15 | N16: 3500 | O16: 15 | P16: 44625 | Q16: 2 | R16: Cash | S16: Neha | T16: kavya.nair@company.com | U16: 9582960180 | V16: Cancelled | W16: =DATEDIF(H16, TODAY(), "y") -> 25 | X16: =IF(OR(ISBLANK(D16), ISBLANK(E16)), "Not Available", E16-D16) -> 12 | Y16: =IF(ISBLANK(E16), "Pending", IF(E16-D16<=5, "On Time ", "Delayed")) -> Delayed
A17: ORD10016 | B17: C010 | C17: P103 | D17: 46120 | E17: 46123 | F17: Pooja Shah | G17: Female | H17: 37357 | I17: Hyderabad | J17: South | K17: Electronics | L17: Keyboard | M17: 3 | N17: 1200 | O17: 5 | P17: 3420 | Q17: 5 | R17: UPI | S17: Ritika | T17: Invalid Email | U17: 9611394005 | V17: Completed | W17: =DATEDIF(H17, TODAY(), "y") -> 24 | X17: =IF(OR(ISBLANK(D17), ISBLANK(E17)), "Not Available", E17-D17) -> 3 | Y17: =IF(ISBLANK(E17), "Pending", IF(E17-D17<=5, "On Time ", "Delayed")) -> On Time
A18: ORD10017 | B18: C004 | C18: P203 | D18: 46075 | E18: 46084 | F18: Amit Sharma | G18: Female | H18: 37272 | I18: Pune | J18: West | K18: Home Appliances | L18: Microwave | M18: 13 | N18: 8500 | O18: 20 | P18: 88400 | Q18: 4 | R18: Card | S18: Rahul | T18: anita.gupta@company.com | U18: 9692599404 | V18: Pending | W18: =DATEDIF(H18, TODAY(), "y") -> 24 | X18: =IF(OR(ISBLANK(D18), ISBLANK(E18)), "Not Available", E18-D18) -> 9 | Y18: =IF(ISBLANK(E18), "Pending", IF(E18-D18<=5, "On Time ", "Delayed")) -> Delayed
A19: ORD10018 | B19: C007 | C19: P203 | D19: 46081 | E19: 46086 | F19: Arjun Rao | G19: Male | H19: 32790 | I19: Ahmedabad | J19: West | K19: Home Appliances | L19: Microwave | M19: 4 | N19: 8500 | O19: 20 | P19: 27200 | Q19: 5 | R19: Card | S19: Aisha | T19: arjun.rao@company.com | U19: 9426119622 | V19: Pending | W19: =DATEDIF(H19, TODAY(), "y") -> 37 | X19: =IF(OR(ISBLANK(D19), ISBLANK(E19)), "Not Available", E19-D19) -> 5 | Y19: =IF(ISBLANK(E19), "Pending", IF(E19-D19<=5, "On Time ", "Delayed")) -> On Time
A20: ORD10019 | B20: C007 | C20: P102 | D20: 45992 | E20: 45995 | F20: Arjun Rao | G20: Male | H20: 33539 | I20: Mumbai | J20: West | K20: Electronics | L20: Mouse | M20: 9 | N20: 700 | O20: 5 | P20: 5985 | Q20: 3 | R20: UPI | S20: Ritika | T20: arjun.rao@company.com | U20: 9184436009 | V20: Pending | W20: =DATEDIF(H20, TODAY(), "y") -> 34 | X20: =IF(OR(ISBLANK(D20), ISBLANK(E20)), "Not Available", E20-D20) -> 3 | Y20: =IF(ISBLANK(E20), "Pending", IF(E20-D20<=5, "On Time ", "Delayed")) -> On Time
... A39: ORD10038 | B39: C006 | C39: P201 | D39: 46089 | E39: 46101 | F39: Sneha Joshi | G39: Female | H39: 29393 | I39: Delhi | J39: North | K39: Home Appliances | L39: Mixer | M39: 20 | N39: 3500 | O39: 10 | P39: 63000 | Q39: 3 | R39: Card | S39: Rahul | T39: sneha.joshi@company.com | U39: 9283578533 | V39: Cancelled | W39: =DATEDIF(H39, TODAY(), "y") -> 46 | X39: =IF(OR(ISBLANK(D39), ISBLANK(E39)), "Not Available", E39-D39) -> 12 | Y39: =IF(ISBLANK(E39), "Pending", IF(E39-D39<=5, "On Time ", "Delayed")) -> Delayed
A40: ORD10039 | B40: C008 | C40: P302 | D40: 45701 | E40: 45707 | F40: Kavya Nair | G40: Female | H40: 29023 | I40: Pune | J40: West | K40: Stationery | L40: Pen | M40: 5 | N40: 1200 | O40: 0 | P40: 100 | Q40: 1 | R40: Cash | S40: Rahul | T40: kavya.nair@company.com | U40: 9963005771 | V40: Cancelled | W40: =DATEDIF(H40, TODAY(), "y") -> 47 | X40: =IF(OR(ISBLANK(D40), ISBLANK(E40)), "Not Available", E40-D40) -> 6 | Y40: =IF(ISBLANK(E40), "Pending", IF(E40-D40<=5, "On Time ", "Delayed")) -> Delayed
A41: ORD10040 | B41: C010 | C41: P203 | D41: 45935 | E41: 45945 | F41: Pooja Shah | G41: Female | H41: 33773 | I41: Mumbai | J41: West | K41: Home Appliances | L41: Microwave | M41: 20 | N41: 8500 | O41: 0 | P41: 170000 | Q41: 1 | R41: UPI | S41: Neha | T41: pooja.shah@company.com | U41: 9484632635 | V41: Cancelled | W41: =DATEDIF(H41, TODAY(), "y") -> 34 | X41: =IF(OR(ISBLANK(D41), ISBLANK(E41)), "Not Available", E41-D41) -> 10 | Y41: =IF(ISBLANK(E41), "Pending", IF(E41-D41<=5, "On Time ", "Delayed")) -> Delayed
A42: ORD10041 | B42: C007 | C42: P301 | D42: 46063 | E42: 46065 | F42: Arjun Rao | G42: Male | H42: 34491 | I42: Bengaluru | J42: South | K42: Stationery | L42: Notebook | M42: 8 | N42: 60 | O42: 15 | P42: 408 | Q42: 5 | R42: UPI | S42: Rahul | T42: arjun.rao@company.com | U42: 9276319484 | V42: Pending | W42: =DATEDIF(H42, TODAY(), "y") -> 32 | X42: =IF(OR(ISBLANK(D42), ISBLANK(E42)), "Not Available", E42-D42) -> 2 | Y42: =IF(ISBLANK(E42), "Pending", IF(E42-D42<=5, "On Time ", "Delayed")) -> On Time
